data/sample_messages.csv
ts,type,id,side,price,qty,new_price,new_qty
1,L,1,B,100000,10,0,0
2,L,2,B,99999,15,0,0
3,L,3,S,100002,12,0,0
4,L,4,S,100003,20,0,0
5,L,5,B,100002,5,0,0
6,M,6,B,0,8,0,0
7,C,2,B,0,0,0,0
8,X,4,S,0,0,100004,25
9,L,7,S,100001,7,0,0
10,L,8,B,100001,30,0,0
